Traceback (most recent call last):
  File "/usr/share/miniconda/envs/analysis/lib/python3.7/site-packages/jupyter_cache/executors/utils.py", line 56, in single_nb_execution
    record_timing=False,
  File "/usr/share/miniconda/envs/analysis/lib/python3.7/site-packages/nbclient/client.py", line 1082, in execute
    return NotebookClient(nb=nb, resources=resources, km=km, **kwargs).execute()
  File "/usr/share/miniconda/envs/analysis/lib/python3.7/site-packages/nbclient/util.py", line 74, in wrapped
    return just_run(coro(*args, **kwargs))
  File "/usr/share/miniconda/envs/analysis/lib/python3.7/site-packages/nbclient/util.py", line 53, in just_run
    return loop.run_until_complete(coro)
  File "/usr/share/miniconda/envs/analysis/lib/python3.7/asyncio/base_events.py", line 587, in run_until_complete
    return future.result()
  File "/usr/share/miniconda/envs/analysis/lib/python3.7/site-packages/nbclient/client.py", line 536, in async_execute
    cell, index, execution_count=self.code_cells_executed + 1
  File "/usr/share/miniconda/envs/analysis/lib/python3.7/site-packages/nbclient/client.py", line 827, in async_execute_cell
    self._check_raise_for_error(cell, exec_reply)
  File "/usr/share/miniconda/envs/analysis/lib/python3.7/site-packages/nbclient/client.py", line 735, in _check_raise_for_error
    raise CellExecutionError.from_cell_and_msg(cell, exec_reply['content'])
nbclient.exceptions.CellExecutionError: An error occurred while executing the following cell:
------------------
import tqdm
# run model inference on test data set
predict_array_cnn = []
label_array_test = []
spec_array_test = []

for t in tqdm.tqdm(test_generator,total=len(test_generator)):
    label_array_test.append(t[1])
    spec_array_test.append(t[2])
    predict_array_cnn.append(keras_model_conv1d.predict(t[0]))
    
predict_array_cnn = np.concatenate(predict_array_cnn,axis=0)
label_array_test = np.concatenate(label_array_test,axis=0)
spec_array_test = np.concatenate(spec_array_test,axis=0)

# create ROC curves
fpr_cnn, tpr_cnn, threshold_cnn = roc_curve(label_array_test[:,1], predict_array_cnn[:,1])
    
# plot ROC curves
plt.figure()
plt.plot(tpr_cnn, fpr_cnn, lw=2.5, label="Conv1D, AUC = {:.1f}%".format(auc(fpr_cnn,tpr_cnn)*100))
plt.xlabel(r'True positive rate')
plt.ylabel(r'False positive rate')
plt.semilogy()
plt.ylim(0.001,1)
plt.xlim(0,1)
plt.grid(True)
plt.legend(loc='upper left')
plt.show()
------------------

[0;31m---------------------------------------------------------------------------[0m
[0;31mModuleNotFoundError[0m                       Traceback (most recent call last)
[0;32m<ipython-input-6-cc69fdf0c090>[0m in [0;36m<module>[0;34m[0m
[0;32m----> 1[0;31m [0;32mimport[0m [0mtqdm[0m[0;34m[0m[0;34m[0m[0m
[0m[1;32m      2[0m [0;31m# run model inference on test data set[0m[0;34m[0m[0;34m[0m[0;34m[0m[0m
[1;32m      3[0m [0mpredict_array_cnn[0m [0;34m=[0m [0;34m[[0m[0;34m][0m[0;34m[0m[0;34m[0m[0m
[1;32m      4[0m [0mlabel_array_test[0m [0;34m=[0m [0;34m[[0m[0;34m][0m[0;34m[0m[0;34m[0m[0m
[1;32m      5[0m [0mspec_array_test[0m [0;34m=[0m [0;34m[[0m[0;34m][0m[0;34m[0m[0;34m[0m[0m

[0;31mModuleNotFoundError[0m: No module named 'tqdm'
ModuleNotFoundError: No module named 'tqdm'

