Traceback (most recent call last):
  File "/usr/share/miniconda/envs/analysis/lib/python3.7/site-packages/jupyter_cache/executors/utils.py", line 56, in single_nb_execution
    record_timing=False,
  File "/usr/share/miniconda/envs/analysis/lib/python3.7/site-packages/nbclient/client.py", line 1082, in execute
    return NotebookClient(nb=nb, resources=resources, km=km, **kwargs).execute()
  File "/usr/share/miniconda/envs/analysis/lib/python3.7/site-packages/nbclient/util.py", line 74, in wrapped
    return just_run(coro(*args, **kwargs))
  File "/usr/share/miniconda/envs/analysis/lib/python3.7/site-packages/nbclient/util.py", line 53, in just_run
    return loop.run_until_complete(coro)
  File "/usr/share/miniconda/envs/analysis/lib/python3.7/asyncio/base_events.py", line 587, in run_until_complete
    return future.result()
  File "/usr/share/miniconda/envs/analysis/lib/python3.7/site-packages/nbclient/client.py", line 536, in async_execute
    cell, index, execution_count=self.code_cells_executed + 1
  File "/usr/share/miniconda/envs/analysis/lib/python3.7/site-packages/nbclient/client.py", line 827, in async_execute_cell
    self._check_raise_for_error(cell, exec_reply)
  File "/usr/share/miniconda/envs/analysis/lib/python3.7/site-packages/nbclient/client.py", line 735, in _check_raise_for_error
    raise CellExecutionError.from_cell_and_msg(cell, exec_reply['content'])
nbclient.exceptions.CellExecutionError: An error occurred while executing the following cell:
------------------
from DataGenerator import DataGenerator
------------------

Traceback [0;36m(most recent call last)[0m:

  File [1;32m"/usr/share/miniconda/envs/analysis/lib/python3.7/site-packages/IPython/core/interactiveshell.py"[0m, line [1;32m3417[0m, in [1;35mrun_code[0m
    exec(code_obj, self.user_global_ns, self.user_ns)

[0;36m  File [0;32m"<ipython-input-3-d4897d4e31d8>"[0;36m, line [0;32m1[0;36m, in [0;35m<module>[0;36m[0m
[0;31m    from DataGenerator import DataGenerator[0m

[0;36m  File [0;32m"/home/runner/work/capstone-particle-physics-domain/capstone-particle-physics-domain/weeks/DataGenerator.py"[0;36m, line [0;32m139[0m
[0;31m    if self.remove_mass_pt_window:[0m
[0m     ^[0m
[0;31mIndentationError[0m[0;31m:[0m expected an indented block

IndentationError: expected an indented block (DataGenerator.py, line 139)

